<mujoco model="tilburg_hand">
<option timestep="0.01111" iterations="50" integrator="Euler" gravity="0 0 -9.81" />
  <default>
    <geom contype="0" conaffinity="0"/>
  </default>
  <compiler angle="radian"/>

  <asset>
    <mesh name="handbase_and_motors_collision" file="handbase_and_motors_collision.stl"/>
    <mesh name="thumb_mcp_collision" file="thumb_mcp_collision.stl"/>
    <mesh name="test_thumb_roll_mcp_collision" file="test_thumb_roll_mcp_collision.stl"/>
    <mesh name="proximal_phalange_collision" file="proximal_phalange_collision.stl"/>
    <mesh name="thumb_distal_collision" file="thumb_distal_collision.stl"/>
    <mesh name="mcp_3_collision" file="mcp_3_collision.stl"/>
    <mesh name="proximal_phalange_2_collision" file="proximal_phalange_2_collision.stl"/>
    <mesh name="middle_phalange_collision" file="middle_phalange_collision.stl"/>
    <mesh name="distal_finalshape_collision" file="distal_finalshape_collision.stl"/>
    <mesh name="mcp_3_2_collision" file="mcp_3_2_collision.stl"/>
    <mesh name="proximal_phalange_3_collision" file="proximal_phalange_3_collision.stl"/>
    <mesh name="middle_phalange_2_collision" file="middle_phalange_2_collision.stl"/>
    <mesh name="distal_finalshape_2_collision" file="distal_finalshape_2_collision.stl"/>
    <mesh name="mcp_3_3_collision" file="mcp_3_3_collision.stl"/>
    <mesh name="proximal_phalange_4_collision" file="proximal_phalange_4_collision.stl"/>
    <mesh name="middle_phalange_3_collision" file="middle_phalange_3_collision.stl"/>
    <mesh name="distal_finalshape_3_collision" file="distal_finalshape_3_collision.stl"/>
  </asset>

  <worldbody>
<body name="hand_base" pos="0 0 0" euler="0 0 0">
    <geom name="handbase_and_motors" friction="1 0.005 0.001" margin="0.001" solimp="0.95 0.95 0.01" solref="0.008 1" type="mesh" rgba="0.480254 0.55963 0.718543 1" mesh="handbase_and_motors_collision"/>
    <body name="thumb_mcp" pos="0.0462379 0.0619979 0.0529852" quat="0.0426663 -0.0206258 -0.706944 0.70568">
      <inertial pos="-0.00336008 0.0104245 0.0140112" quat="0.705399 0.708685 -0.00389937 -0.0127609" mass="0.0259261" diaginertia="4.44074e-06 4.37503e-06 2.95984e-06"/>
      <joint damping="0.1" stiffness="0.5" armature="0.01" frictionloss="0.01" ref="0" springref="0" margin="0.01" name="thumb_cmc" pos="0 0 0" axis="0 0 1" range="0 1.5708" actuatorfrcrange="-0.35 0.35"/>
      <geom name="thumb_thumb_mcp" friction="1 0.005 0.001" margin="0.001" solimp="0.95 0.95 0.01" solref="0.008 1" type="mesh" rgba="0.871558 0.93709 0.976409 1" mesh="thumb_mcp_collision"/>
      <body name="test_thumb_roll_mcp" pos="-0.01699 0 0.014" quat="0.707087 -0.0052599 -0.707087 0.0052599">
        <inertial pos="-0.000503967 0.00367437 0.00891183" quat="0.441307 0.548539 0.474465 0.528428" mass="0.0051287" diaginertia="1.09205e-06 9.52622e-07 4.71781e-07"/>
        <joint damping="0.1" stiffness="0.5" armature="0.01" frictionloss="0.01" ref="0" springref="0" margin="0.01" name="thumb_mcp_rot" pos="0 0 0" axis="0 0 1" range="-1.74533 0" actuatorfrcrange="-0.35 0.35"/>
        <geom name="thumb_test_thumb_roll_mcp" friction="1 0.005 0.001" margin="0.001" solimp="0.95 0.95 0.01" solref="0.008 1" type="mesh" rgba="0.231373 0.380392 0.705882 1" mesh="test_thumb_roll_mcp_collision"/>
        <body name="proximal_phalange" pos="0.0131 -1.07477e-06 0.0185" quat="0.502265 -0.497725 0.502265 -0.497725">
          <inertial pos="0.000290464 -0.0248 -0.0139996" quat="0.70708 0.70708 0.0061953 -0.0061953" mass="0.0442258" diaginertia="1.83091e-05 1.7756e-05 4.94746e-06"/>
          <joint damping="0.1" stiffness="0.5" armature="0.01" frictionloss="0.01" ref="0" springref="0" margin="0.01" name="thumb_mcp" pos="0 0 0" axis="0 0 1" range="0 1.5708" actuatorfrcrange="-0.35 0.35"/>
          <geom name="thumb_proximal_phalange" friction="1 0.005 0.001" margin="0.001" solimp="0.95 0.95 0.01" solref="0.008 1" type="mesh" rgba="0.995698 0.95113 0.825267 1" mesh="proximal_phalange_collision"/>
          <body name="thumb_distal" pos="0 -0.0496 0" quat="0.707104 0 0 -0.70711">
            <inertial pos="0.0363127 4.71179e-05 -0.0132934" quat="0.490269 0.488734 0.507649 0.512902" mass="0.01279" diaginertia="5.84542e-06 5.17804e-06 1.76804e-06"/>
            <joint damping="0.1" stiffness="0.5" armature="0.01" frictionloss="0.01" ref="0" springref="0" margin="0.01" name="thumb_ip" pos="0 0 0" axis="0 0 1" range="0 1.6581" actuatorfrcrange="-0.35 0.35"/>
            <geom name="thumb_thumb_distal" friction="1 0.005 0.001" margin="0.001" solimp="0.95 0.95 0.01" solref="0.008 1" type="mesh" rgba="0.513726 0.415686 0.733333 1" mesh="thumb_distal_collision"/>
          </body>
        </body>
      </body>
    </body>
    <body name="mcp_3" pos="0.0540379 0.120346 0.0649955" quat="0.999 0.000219053 0.000521299 -0.0446977">
      <inertial pos="-0.00048757 0.0155243 -0.0117405" quat="0.719022 -0.283303 0.16479 0.612855" mass="0.00917755" diaginertia="2.25958e-06 2.05723e-06 1.86647e-06"/>
      <joint damping="0.1" stiffness="0.5" armature="0.01" frictionloss="0.01" ref="0" springref="0" margin="0.01" name="index_mcp_abadd" pos="0 0 0" axis="0 0 1" range="-0.436332 0.436332" actuatorfrcrange="-0.35 0.35"/>
      <geom name="index_mcp_3" friction="1 0.005 0.001" margin="0.001" solimp="0.95 0.95 0.01" solref="0.008 1" type="mesh" rgba="0.231373 0.380392 0.705882 1" mesh="mcp_3_collision"/>
      <body name="proximal_phalange_2" pos="0.0131 0.0325 -0.00659893" quat="0.0256174 0.706643 0.0256174 0.706643">
        <inertial pos="0.000290464 -0.0248 -0.0139996" quat="0.70708 0.70708 0.0061953 -0.0061953" mass="0.0442258" diaginertia="1.83091e-05 1.7756e-05 4.94746e-06"/>
        <joint damping="0.1" stiffness="0.5" armature="0.01" frictionloss="0.01" ref="0" springref="0" margin="0.01" name="index_mcp" pos="0 0 0" axis="0 0 1" range="-0.0873 1.6581" actuatorfrcrange="-0.35 0.35"/>
        <geom name="index_proximal_phalange_2" friction="1 0.005 0.001" margin="0.001" solimp="0.95 0.95 0.01" solref="0.008 1" type="mesh" rgba="0.995698 0.95113 0.825267 1" mesh="proximal_phalange_2_collision"/>
        <body name="middle_phalange" pos="0 -0.0496 0" quat="0.67569 0 0 -0.737186">
          <inertial pos="0.0299115 0.00075866 -0.0138424" quat="0.488832 0.485623 0.505181 0.519621" mass="0.0256181" diaginertia="6.4616e-06 5.47097e-06 3.01437e-06"/>
          <joint damping="0.1" stiffness="0.5" armature="0.01" frictionloss="0.01" ref="0" springref="0" margin="0.01" name="index_pip" pos="0 0 0" axis="0 0 1" range="-0.0873 1.6581" actuatorfrcrange="-0.35 0.35"/>
          <geom name="index_middle_phalange" friction="1 0.005 0.001" margin="0.001" solimp="0.95 0.95 0.01" solref="0.008 1" type="mesh" rgba="0.959064 0.819626 0.777411 1" mesh="middle_phalange_collision"/>
          <body name="distal_finalshape" pos="0.0423 0 -1e-05" quat="0.99905 0.000871836 3.80276e-05 -0.0435764">
            <inertial pos="0.028182 -0.000109832 -0.0133084" quat="0.484783 0.47974 0.511816 0.52238" mass="0.00905" diaginertia="2.94805e-06 2.40857e-06 1.27278e-06"/>
            <joint damping="0.1" stiffness="0.5" armature="0.01" frictionloss="0.01" ref="0" springref="0" margin="0.01" name="index_dip" pos="0 0 0" axis="0 0 1" range="-0.0873 1.6581" actuatorfrcrange="-0.35 0.35"/>
            <geom name="index_distal_finalshape" friction="1 0.005 0.001" margin="0.001" solimp="0.95 0.95 0.01" solref="0.008 1" type="mesh" rgba="0.513726 0.415686 0.733333 1" mesh="distal_finalshape_collision"/>
          </body>
        </body>
      </body>
    </body>
    <body name="mcp_3_2" pos="0.009956 0.122372 0.0650415" quat="0.999999 0.00024155 0.000511263 -0.00114438">
      <inertial pos="-0.00048757 0.0155243 -0.0117405" quat="0.719022 -0.283303 0.16479 0.612855" mass="0.00917755" diaginertia="2.25958e-06 2.05723e-06 1.86647e-06"/>
      <joint damping="0.1" stiffness="0.5" armature="0.01" frictionloss="0.01" ref="0" springref="0" margin="0.01" name="middle_mcp_abadd" pos="0 0 0" axis="0 0 1" range="-0.436332 0.436332" actuatorfrcrange="-0.35 0.35"/>
      <geom name="middle_mcp_3_2" friction="1 0.005 0.001" margin="0.001" solimp="0.95 0.95 0.01" solref="0.008 1" type="mesh" rgba="0.231373 0.380392 0.705882 1" mesh="mcp_3_2_collision"/>
      <body name="proximal_phalange_3" pos="0.0131 0.0325 -0.00659893" quat="0.0247065 0.706675 0.0247065 0.706675">
        <inertial pos="0.000290464 -0.0248 -0.0139996" quat="0.70708 0.70708 0.0061953 -0.0061953" mass="0.0442258" diaginertia="1.83091e-05 1.7756e-05 4.94746e-06"/>
        <joint damping="0.1" stiffness="0.5" armature="0.01" frictionloss="0.01" ref="0" springref="0" margin="0.01" name="middle_mcp" pos="0 0 0" axis="0 0 1" range="-0.0873 1.6581" actuatorfrcrange="-0.35 0.35"/>
        <geom name="middle_proximal_phalange_3" friction="1 0.005 0.001" margin="0.001" solimp="0.95 0.95 0.01" solref="0.008 1" type="mesh" rgba="0.995698 0.95113 0.825267 1" mesh="proximal_phalange_3_collision"/>
        <body name="middle_phalange_2" pos="0 -0.0496 0" quat="0.675687 0 0 -0.737189">
          <inertial pos="0.0299115 0.00075866 -0.0138424" quat="0.488832 0.485623 0.505181 0.519621" mass="0.0256181" diaginertia="6.4616e-06 5.47097e-06 3.01437e-06"/>
          <joint damping="0.1" stiffness="0.5" armature="0.01" frictionloss="0.01" ref="0" springref="0" margin="0.01" name="middle_pip" pos="0 0 0" axis="0 0 1" range="-0.0873 1.6581" actuatorfrcrange="-0.35 0.35"/>
          <geom name="middle_middle_phalange_2" friction="1 0.005 0.001" margin="0.001" solimp="0.95 0.95 0.01" solref="0.008 1" type="mesh" rgba="0.959064 0.819626 0.777411 1" mesh="middle_phalange_2_collision"/>
          <body name="distal_finalshape_2" pos="0.0423 0 -1e-05" quat="0.99905 0.000871836 3.80276e-05 -0.0435764">
            <inertial pos="0.028182 -0.000109832 -0.0133084" quat="0.484783 0.47974 0.511816 0.52238" mass="0.00905" diaginertia="2.94805e-06 2.40857e-06 1.27278e-06"/>
            <joint damping="0.1" stiffness="0.5" armature="0.01" frictionloss="0.01" ref="0" springref="0" margin="0.01" name="middle_dip" pos="0 0 0" axis="0 0 1" range="-0.0873 1.6581" actuatorfrcrange="-0.35 0.35"/>
            <geom name="middle_distal_finalshape_2" friction="1 0.005 0.001" margin="0.001" solimp="0.95 0.95 0.01" solref="0.008 1" type="mesh" rgba="0.513726 0.415686 0.733333 1" mesh="distal_finalshape_2_collision"/>
          </body>
        </body>
      </body>
    </body>
    <body name="mcp_3_3" pos="-0.0346372 0.120001 0.0680959" quat="0.9991 0.000263588 0.000500258 0.0424111">
      <inertial pos="-0.00048757 0.0155243 -0.0117405" quat="0.719022 -0.283303 0.16479 0.612855" mass="0.00917755" diaginertia="2.25958e-06 2.05723e-06 1.86647e-06"/>
      <joint damping="0.1" stiffness="0.5" armature="0.01" frictionloss="0.01" ref="0" springref="0" margin="0.01" name="ring_mcp_abadd" pos="0 0 0" axis="0 0 1" range="-0.436332 0.436332" actuatorfrcrange="-0.35 0.35"/>
      <geom name="ring_mcp_3_3" friction="1 0.005 0.001" margin="0.001" solimp="0.95 0.95 0.01" solref="0.008 1" type="mesh" rgba="0.231373 0.380392 0.705882 1" mesh="mcp_3_3_collision"/>
      <body name="proximal_phalange_4" pos="0.0131 0.0325 -0.00659893" quat="0.0238426 0.706705 0.0238426 0.706705">
        <inertial pos="0.000290464 -0.0248 -0.0139996" quat="0.70708 0.70708 0.0061953 -0.0061953" mass="0.0442258" diaginertia="1.83091e-05 1.7756e-05 4.94746e-06"/>
        <joint damping="0.1" stiffness="0.5" armature="0.01" frictionloss="0.01" ref="0" springref="0" margin="0.01" name="ring_mcp" pos="0 0 0" axis="0 0 1" range="-0.0873 1.6581" actuatorfrcrange="-0.35 0.35"/>
        <geom name="ring_proximal_phalange_4" friction="1 0.005 0.001" margin="0.001" solimp="0.95 0.95 0.01" solref="0.008 1" type="mesh" rgba="0.995698 0.95113 0.825267 1" mesh="proximal_phalange_4_collision"/>
        <body name="middle_phalange_3" pos="0 -0.0496 0" quat="0.675684 0 0 -0.737191">
          <inertial pos="0.0299115 0.00075866 -0.0138424" quat="0.488832 0.485623 0.505181 0.519621" mass="0.0256181" diaginertia="6.4616e-06 5.47097e-06 3.01437e-06"/>
          <joint damping="0.1" stiffness="0.5" armature="0.01" frictionloss="0.01" ref="0" springref="0" margin="0.01" name="ring_pip" pos="0 0 0" axis="0 0 1" range="-0.0873 1.6581" actuatorfrcrange="-0.35 0.35"/>
          <geom name="ring_middle_phalange_3" friction="1 0.005 0.001" margin="0.001" solimp="0.95 0.95 0.01" solref="0.008 1" type="mesh" rgba="0.959064 0.819626 0.777411 1" mesh="middle_phalange_3_collision"/>
          <body name="distal_finalshape_3" pos="0.0423 0 -1e-05" quat="0.99905 0.000871836 3.80272e-05 -0.0435759">
            <inertial pos="0.028182 -0.000109832 -0.0133084" quat="0.484783 0.47974 0.511816 0.52238" mass="0.00905" diaginertia="2.94805e-06 2.40857e-06 1.27278e-06"/>
            <joint damping="0.1" stiffness="0.5" armature="0.01" frictionloss="0.01" ref="0" springref="0" margin="0.01" name="ring_dip" pos="0 0 0" axis="0 0 1" range="-0.0873 1.6581" actuatorfrcrange="-0.35 0.35"/>
            <geom name="ring_distal_finalshape_3" friction="1 0.005 0.001" margin="0.001" solimp="0.95 0.95 0.01" solref="0.008 1" type="mesh" rgba="0.513726 0.415686 0.733333 1" mesh="distal_finalshape_3_collision"/>
          </body>
        </body>
      </body>
    </body>
</body>  </worldbody>
<actuator><position ctrllimited="true" forcelimited="true" forcerange="-3 3" kp="100" gear="1" ctrlrange="0 1.5708" joint="thumb_cmc" name="thumb_cmc"></position>
<position ctrllimited="true" forcelimited="true" forcerange="-3 3" kp="100" gear="1" ctrlrange="-1.74533 0" joint="thumb_mcp_rot" name="thumb_mcp_rot"></position>
<position ctrllimited="true" forcelimited="true" forcerange="-3 3" kp="100" gear="1" ctrlrange="0 1.5708" joint="thumb_mcp" name="thumb_mcp"></position>
<position ctrllimited="true" forcelimited="true" forcerange="-3 3" kp="100" gear="1" ctrlrange="0 1.6581" joint="thumb_ip" name="thumb_ip"></position>
<position ctrllimited="true" forcelimited="true" forcerange="-3 3" kp="100" gear="1" ctrlrange="-0.436332 0.436332" joint="index_mcp_abadd" name="index_mcp_abadd"></position>
<position ctrllimited="true" forcelimited="true" forcerange="-3 3" kp="100" gear="1" ctrlrange="-0.0873 1.6581" joint="index_mcp" name="index_mcp"></position>
<position ctrllimited="true" forcelimited="true" forcerange="-3 3" kp="100" gear="1" ctrlrange="-0.0873 1.6581" joint="index_pip" name="index_pip"></position>
<position ctrllimited="true" forcelimited="true" forcerange="-3 3" kp="100" gear="1" ctrlrange="-0.0873 1.6581" joint="index_dip" name="index_dip"></position>
<position ctrllimited="true" forcelimited="true" forcerange="-3 3" kp="100" gear="1" ctrlrange="-0.436332 0.436332" joint="middle_mcp_abadd" name="middle_mcp_abadd"></position>
<position ctrllimited="true" forcelimited="true" forcerange="-3 3" kp="100" gear="1" ctrlrange="-0.0873 1.6581" joint="middle_mcp" name="middle_mcp"></position>
<position ctrllimited="true" forcelimited="true" forcerange="-3 3" kp="100" gear="1" ctrlrange="-0.0873 1.6581" joint="middle_pip" name="middle_pip"></position>
<position ctrllimited="true" forcelimited="true" forcerange="-3 3" kp="100" gear="1" ctrlrange="-0.0873 1.6581" joint="middle_dip" name="middle_dip"></position>
<position ctrllimited="true" forcelimited="true" forcerange="-3 3" kp="100" gear="1" ctrlrange="-0.436332 0.436332" joint="ring_mcp_abadd" name="ring_mcp_abadd"></position>
<position ctrllimited="true" forcelimited="true" forcerange="-3 3" kp="100" gear="1" ctrlrange="-0.0873 1.6581" joint="ring_mcp" name="ring_mcp"></position>
<position ctrllimited="true" forcelimited="true" forcerange="-3 3" kp="100" gear="1" ctrlrange="-0.0873 1.6581" joint="ring_pip" name="ring_pip"></position>
<position ctrllimited="true" forcelimited="true" forcerange="-3 3" kp="100" gear="1" ctrlrange="-0.0873 1.6581" joint="ring_dip" name="ring_dip"></position>
</actuator>
<contact><pair geom1="thumb_proximal_phalange" geom2="index_mcp_3" condim="3" friction="1 0.005 0.001" margin="0.0005" solimp="0.95 0.95 0.01" solref="0.008 1" /><pair geom1="thumb_proximal_phalange" geom2="index_proximal_phalange_2" condim="3" friction="1 0.005 0.001" margin="0.0005" solimp="0.95 0.95 0.01" solref="0.008 1" /><pair geom1="thumb_proximal_phalange" geom2="index_middle_phalange" condim="3" friction="1 0.005 0.001" margin="0.0005" solimp="0.95 0.95 0.01" solref="0.008 1" /><pair geom1="thumb_proximal_phalange" geom2="index_distal_finalshape" condim="3" friction="1 0.005 0.001" margin="0.0005" solimp="0.95 0.95 0.01" solref="0.008 1" /><pair geom1="thumb_proximal_phalange" geom2="middle_mcp_3_2" condim="3" friction="1 0.005 0.001" margin="0.0005" solimp="0.95 0.95 0.01" solref="0.008 1" /><pair geom1="thumb_proximal_phalange" geom2="middle_proximal_phalange_3" condim="3" friction="1 0.005 0.001" margin="0.0005" solimp="0.95 0.95 0.01" solref="0.008 1" /><pair geom1="thumb_proximal_phalange" geom2="middle_middle_phalange_2" condim="3" friction="1 0.005 0.001" margin="0.0005" solimp="0.95 0.95 0.01" solref="0.008 1" /><pair geom1="thumb_proximal_phalange" geom2="middle_distal_finalshape_2" condim="3" friction="1 0.005 0.001" margin="0.0005" solimp="0.95 0.95 0.01" solref="0.008 1" /><pair geom1="thumb_proximal_phalange" geom2="ring_mcp_3_3" condim="3" friction="1 0.005 0.001" margin="0.0005" solimp="0.95 0.95 0.01" solref="0.008 1" /><pair geom1="thumb_proximal_phalange" geom2="ring_proximal_phalange_4" condim="3" friction="1 0.005 0.001" margin="0.0005" solimp="0.95 0.95 0.01" solref="0.008 1" /><pair geom1="thumb_proximal_phalange" geom2="ring_middle_phalange_3" condim="3" friction="1 0.005 0.001" margin="0.0005" solimp="0.95 0.95 0.01" solref="0.008 1" /><pair geom1="thumb_proximal_phalange" geom2="ring_distal_finalshape_3" condim="3" friction="1 0.005 0.001" margin="0.0005" solimp="0.95 0.95 0.01" solref="0.008 1" /><pair geom1="handbase_and_motors" geom2="thumb_thumb_distal" condim="3" friction="1 0.005 0.001" margin="0.0005" solimp="0.95 0.95 0.01" solref="0.008 1" /><pair geom1="thumb_thumb_distal" geom2="index_mcp_3" condim="3" friction="1 0.005 0.001" margin="0.0005" solimp="0.95 0.95 0.01" solref="0.008 1" /><pair geom1="thumb_thumb_distal" geom2="index_proximal_phalange_2" condim="3" friction="1 0.005 0.001" margin="0.0005" solimp="0.95 0.95 0.01" solref="0.008 1" /><pair geom1="thumb_thumb_distal" geom2="index_middle_phalange" condim="3" friction="1 0.005 0.001" margin="0.0005" solimp="0.95 0.95 0.01" solref="0.008 1" /><pair geom1="thumb_thumb_distal" geom2="index_distal_finalshape" condim="3" friction="1 0.005 0.001" margin="0.0005" solimp="0.95 0.95 0.01" solref="0.008 1" /><pair geom1="thumb_thumb_distal" geom2="middle_mcp_3_2" condim="3" friction="1 0.005 0.001" margin="0.0005" solimp="0.95 0.95 0.01" solref="0.008 1" /><pair geom1="thumb_thumb_distal" geom2="middle_proximal_phalange_3" condim="3" friction="1 0.005 0.001" margin="0.0005" solimp="0.95 0.95 0.01" solref="0.008 1" /><pair geom1="thumb_thumb_distal" geom2="middle_middle_phalange_2" condim="3" friction="1 0.005 0.001" margin="0.0005" solimp="0.95 0.95 0.01" solref="0.008 1" /><pair geom1="thumb_thumb_distal" geom2="middle_distal_finalshape_2" condim="3" friction="1 0.005 0.001" margin="0.0005" solimp="0.95 0.95 0.01" solref="0.008 1" /><pair geom1="thumb_thumb_distal" geom2="ring_mcp_3_3" condim="3" friction="1 0.005 0.001" margin="0.0005" solimp="0.95 0.95 0.01" solref="0.008 1" /><pair geom1="thumb_thumb_distal" geom2="ring_proximal_phalange_4" condim="3" friction="1 0.005 0.001" margin="0.0005" solimp="0.95 0.95 0.01" solref="0.008 1" /><pair geom1="thumb_thumb_distal" geom2="ring_middle_phalange_3" condim="3" friction="1 0.005 0.001" margin="0.0005" solimp="0.95 0.95 0.01" solref="0.008 1" /><pair geom1="thumb_thumb_distal" geom2="ring_distal_finalshape_3" condim="3" friction="1 0.005 0.001" margin="0.0005" solimp="0.95 0.95 0.01" solref="0.008 1" /><pair geom1="index_mcp_3" geom2="index_distal_finalshape" condim="3" friction="1 0.005 0.001" margin="0.0005" solimp="0.95 0.95 0.01" solref="0.008 1" /><pair geom1="index_proximal_phalange_2" geom2="index_distal_finalshape" condim="3" friction="1 0.005 0.001" margin="0.0005" solimp="0.95 0.95 0.01" solref="0.008 1" /><pair geom1="index_mcp_3" geom2="middle_mcp_3_2" condim="3" friction="1 0.005 0.001" margin="0.0005" solimp="0.95 0.95 0.01" solref="0.008 1" /><pair geom1="index_mcp_3" geom2="middle_proximal_phalange_3" condim="3" friction="1 0.005 0.001" margin="0.0005" solimp="0.95 0.95 0.01" solref="0.008 1" /><pair geom1="index_mcp_3" geom2="middle_middle_phalange_2" condim="3" friction="1 0.005 0.001" margin="0.0005" solimp="0.95 0.95 0.01" solref="0.008 1" /><pair geom1="index_mcp_3" geom2="middle_distal_finalshape_2" condim="3" friction="1 0.005 0.001" margin="0.0005" solimp="0.95 0.95 0.01" solref="0.008 1" /><pair geom1="index_mcp_3" geom2="ring_mcp_3_3" condim="3" friction="1 0.005 0.001" margin="0.0005" solimp="0.95 0.95 0.01" solref="0.008 1" /><pair geom1="index_mcp_3" geom2="ring_proximal_phalange_4" condim="3" friction="1 0.005 0.001" margin="0.0005" solimp="0.95 0.95 0.01" solref="0.008 1" /><pair geom1="index_mcp_3" geom2="ring_middle_phalange_3" condim="3" friction="1 0.005 0.001" margin="0.0005" solimp="0.95 0.95 0.01" solref="0.008 1" /><pair geom1="index_mcp_3" geom2="ring_distal_finalshape_3" condim="3" friction="1 0.005 0.001" margin="0.0005" solimp="0.95 0.95 0.01" solref="0.008 1" /><pair geom1="index_proximal_phalange_2" geom2="middle_mcp_3_2" condim="3" friction="1 0.005 0.001" margin="0.0005" solimp="0.95 0.95 0.01" solref="0.008 1" /><pair geom1="index_proximal_phalange_2" geom2="middle_proximal_phalange_3" condim="3" friction="1 0.005 0.001" margin="0.0005" solimp="0.95 0.95 0.01" solref="0.008 1" /><pair geom1="index_proximal_phalange_2" geom2="middle_middle_phalange_2" condim="3" friction="1 0.005 0.001" margin="0.0005" solimp="0.95 0.95 0.01" solref="0.008 1" /><pair geom1="index_proximal_phalange_2" geom2="middle_distal_finalshape_2" condim="3" friction="1 0.005 0.001" margin="0.0005" solimp="0.95 0.95 0.01" solref="0.008 1" /><pair geom1="index_proximal_phalange_2" geom2="ring_mcp_3_3" condim="3" friction="1 0.005 0.001" margin="0.0005" solimp="0.95 0.95 0.01" solref="0.008 1" /><pair geom1="index_proximal_phalange_2" geom2="ring_proximal_phalange_4" condim="3" friction="1 0.005 0.001" margin="0.0005" solimp="0.95 0.95 0.01" solref="0.008 1" /><pair geom1="index_proximal_phalange_2" geom2="ring_middle_phalange_3" condim="3" friction="1 0.005 0.001" margin="0.0005" solimp="0.95 0.95 0.01" solref="0.008 1" /><pair geom1="index_proximal_phalange_2" geom2="ring_distal_finalshape_3" condim="3" friction="1 0.005 0.001" margin="0.0005" solimp="0.95 0.95 0.01" solref="0.008 1" /><pair geom1="index_middle_phalange" geom2="middle_mcp_3_2" condim="3" friction="1 0.005 0.001" margin="0.0005" solimp="0.95 0.95 0.01" solref="0.008 1" /><pair geom1="index_middle_phalange" geom2="middle_proximal_phalange_3" condim="3" friction="1 0.005 0.001" margin="0.0005" solimp="0.95 0.95 0.01" solref="0.008 1" /><pair geom1="index_middle_phalange" geom2="middle_middle_phalange_2" condim="3" friction="1 0.005 0.001" margin="0.0005" solimp="0.95 0.95 0.01" solref="0.008 1" /><pair geom1="index_middle_phalange" geom2="middle_distal_finalshape_2" condim="3" friction="1 0.005 0.001" margin="0.0005" solimp="0.95 0.95 0.01" solref="0.008 1" /><pair geom1="index_middle_phalange" geom2="ring_mcp_3_3" condim="3" friction="1 0.005 0.001" margin="0.0005" solimp="0.95 0.95 0.01" solref="0.008 1" /><pair geom1="index_middle_phalange" geom2="ring_proximal_phalange_4" condim="3" friction="1 0.005 0.001" margin="0.0005" solimp="0.95 0.95 0.01" solref="0.008 1" /><pair geom1="index_middle_phalange" geom2="ring_middle_phalange_3" condim="3" friction="1 0.005 0.001" margin="0.0005" solimp="0.95 0.95 0.01" solref="0.008 1" /><pair geom1="index_middle_phalange" geom2="ring_distal_finalshape_3" condim="3" friction="1 0.005 0.001" margin="0.0005" solimp="0.95 0.95 0.01" solref="0.008 1" /><pair geom1="handbase_and_motors" geom2="index_distal_finalshape" condim="3" friction="1 0.005 0.001" margin="0.0005" solimp="0.95 0.95 0.01" solref="0.008 1" /><pair geom1="index_distal_finalshape" geom2="middle_mcp_3_2" condim="3" friction="1 0.005 0.001" margin="0.0005" solimp="0.95 0.95 0.01" solref="0.008 1" /><pair geom1="index_distal_finalshape" geom2="middle_proximal_phalange_3" condim="3" friction="1 0.005 0.001" margin="0.0005" solimp="0.95 0.95 0.01" solref="0.008 1" /><pair geom1="index_distal_finalshape" geom2="middle_middle_phalange_2" condim="3" friction="1 0.005 0.001" margin="0.0005" solimp="0.95 0.95 0.01" solref="0.008 1" /><pair geom1="index_distal_finalshape" geom2="middle_distal_finalshape_2" condim="3" friction="1 0.005 0.001" margin="0.0005" solimp="0.95 0.95 0.01" solref="0.008 1" /><pair geom1="index_distal_finalshape" geom2="ring_mcp_3_3" condim="3" friction="1 0.005 0.001" margin="0.0005" solimp="0.95 0.95 0.01" solref="0.008 1" /><pair geom1="index_distal_finalshape" geom2="ring_proximal_phalange_4" condim="3" friction="1 0.005 0.001" margin="0.0005" solimp="0.95 0.95 0.01" solref="0.008 1" /><pair geom1="index_distal_finalshape" geom2="ring_middle_phalange_3" condim="3" friction="1 0.005 0.001" margin="0.0005" solimp="0.95 0.95 0.01" solref="0.008 1" /><pair geom1="index_distal_finalshape" geom2="ring_distal_finalshape_3" condim="3" friction="1 0.005 0.001" margin="0.0005" solimp="0.95 0.95 0.01" solref="0.008 1" /><pair geom1="middle_mcp_3_2" geom2="middle_distal_finalshape_2" condim="3" friction="1 0.005 0.001" margin="0.0005" solimp="0.95 0.95 0.01" solref="0.008 1" /><pair geom1="middle_proximal_phalange_3" geom2="middle_distal_finalshape_2" condim="3" friction="1 0.005 0.001" margin="0.0005" solimp="0.95 0.95 0.01" solref="0.008 1" /><pair geom1="middle_mcp_3_2" geom2="ring_mcp_3_3" condim="3" friction="1 0.005 0.001" margin="0.0005" solimp="0.95 0.95 0.01" solref="0.008 1" /><pair geom1="middle_mcp_3_2" geom2="ring_proximal_phalange_4" condim="3" friction="1 0.005 0.001" margin="0.0005" solimp="0.95 0.95 0.01" solref="0.008 1" /><pair geom1="middle_mcp_3_2" geom2="ring_middle_phalange_3" condim="3" friction="1 0.005 0.001" margin="0.0005" solimp="0.95 0.95 0.01" solref="0.008 1" /><pair geom1="middle_mcp_3_2" geom2="ring_distal_finalshape_3" condim="3" friction="1 0.005 0.001" margin="0.0005" solimp="0.95 0.95 0.01" solref="0.008 1" /><pair geom1="middle_proximal_phalange_3" geom2="ring_mcp_3_3" condim="3" friction="1 0.005 0.001" margin="0.0005" solimp="0.95 0.95 0.01" solref="0.008 1" /><pair geom1="middle_proximal_phalange_3" geom2="ring_proximal_phalange_4" condim="3" friction="1 0.005 0.001" margin="0.0005" solimp="0.95 0.95 0.01" solref="0.008 1" /><pair geom1="middle_proximal_phalange_3" geom2="ring_middle_phalange_3" condim="3" friction="1 0.005 0.001" margin="0.0005" solimp="0.95 0.95 0.01" solref="0.008 1" /><pair geom1="middle_proximal_phalange_3" geom2="ring_distal_finalshape_3" condim="3" friction="1 0.005 0.001" margin="0.0005" solimp="0.95 0.95 0.01" solref="0.008 1" /><pair geom1="middle_middle_phalange_2" geom2="ring_mcp_3_3" condim="3" friction="1 0.005 0.001" margin="0.0005" solimp="0.95 0.95 0.01" solref="0.008 1" /><pair geom1="middle_middle_phalange_2" geom2="ring_proximal_phalange_4" condim="3" friction="1 0.005 0.001" margin="0.0005" solimp="0.95 0.95 0.01" solref="0.008 1" /><pair geom1="middle_middle_phalange_2" geom2="ring_middle_phalange_3" condim="3" friction="1 0.005 0.001" margin="0.0005" solimp="0.95 0.95 0.01" solref="0.008 1" /><pair geom1="middle_middle_phalange_2" geom2="ring_distal_finalshape_3" condim="3" friction="1 0.005 0.001" margin="0.0005" solimp="0.95 0.95 0.01" solref="0.008 1" /><pair geom1="handbase_and_motors" geom2="middle_distal_finalshape_2" condim="3" friction="1 0.005 0.001" margin="0.0005" solimp="0.95 0.95 0.01" solref="0.008 1" /><pair geom1="middle_distal_finalshape_2" geom2="ring_mcp_3_3" condim="3" friction="1 0.005 0.001" margin="0.0005" solimp="0.95 0.95 0.01" solref="0.008 1" /><pair geom1="middle_distal_finalshape_2" geom2="ring_proximal_phalange_4" condim="3" friction="1 0.005 0.001" margin="0.0005" solimp="0.95 0.95 0.01" solref="0.008 1" /><pair geom1="middle_distal_finalshape_2" geom2="ring_middle_phalange_3" condim="3" friction="1 0.005 0.001" margin="0.0005" solimp="0.95 0.95 0.01" solref="0.008 1" /><pair geom1="middle_distal_finalshape_2" geom2="ring_distal_finalshape_3" condim="3" friction="1 0.005 0.001" margin="0.0005" solimp="0.95 0.95 0.01" solref="0.008 1" /><pair geom1="ring_mcp_3_3" geom2="ring_distal_finalshape_3" condim="3" friction="1 0.005 0.001" margin="0.0005" solimp="0.95 0.95 0.01" solref="0.008 1" /><pair geom1="ring_proximal_phalange_4" geom2="ring_distal_finalshape_3" condim="3" friction="1 0.005 0.001" margin="0.0005" solimp="0.95 0.95 0.01" solref="0.008 1" /><pair geom1="handbase_and_motors" geom2="ring_distal_finalshape_3" condim="3" friction="1 0.005 0.001" margin="0.0005" solimp="0.95 0.95 0.01" solref="0.008 1" /></contact></mujoco>
